[2023-10-23T12:41:49.799+0000] {taskinstance.py:1159} INFO - Dependencies all met for dep_context=non-requeueable deps ti=<TaskInstance: once_ingestion_gcs_dag.fetch_and_save_to_local_task manual__2023-10-23T12:31:01.467482+00:00 [queued]>
[2023-10-23T12:41:49.813+0000] {taskinstance.py:1159} INFO - Dependencies all met for dep_context=requeueable deps ti=<TaskInstance: once_ingestion_gcs_dag.fetch_and_save_to_local_task manual__2023-10-23T12:31:01.467482+00:00 [queued]>
[2023-10-23T12:41:49.813+0000] {taskinstance.py:1361} INFO - Starting attempt 1 of 2
[2023-10-23T12:41:49.833+0000] {taskinstance.py:1382} INFO - Executing <Task(PythonOperator): fetch_and_save_to_local_task> on 2023-10-23 12:31:01.467482+00:00
[2023-10-23T12:41:49.844+0000] {standard_task_runner.py:57} INFO - Started process 229 to run task
[2023-10-23T12:41:49.854+0000] {standard_task_runner.py:84} INFO - Running: ['***', 'tasks', 'run', 'once_ingestion_gcs_dag', 'fetch_and_save_to_local_task', 'manual__2023-10-23T12:31:01.467482+00:00', '--job-id', '6', '--raw', '--subdir', 'DAGS_FOLDER/once_ingest_data_to_gcs_dag.py', '--cfg-path', '/tmp/tmp0ynonvxk']
[2023-10-23T12:41:49.862+0000] {standard_task_runner.py:85} INFO - Job 6: Subtask fetch_and_save_to_local_task
[2023-10-23T12:41:49.950+0000] {task_command.py:416} INFO - Running <TaskInstance: once_ingestion_gcs_dag.fetch_and_save_to_local_task manual__2023-10-23T12:31:01.467482+00:00 [running]> on host c698a5494e22
[2023-10-23T12:41:50.056+0000] {taskinstance.py:1662} INFO - Exporting env vars: AIRFLOW_CTX_DAG_OWNER='***' AIRFLOW_CTX_DAG_ID='once_ingestion_gcs_dag' AIRFLOW_CTX_TASK_ID='fetch_and_save_to_local_task' AIRFLOW_CTX_EXECUTION_DATE='2023-10-23T12:31:01.467482+00:00' AIRFLOW_CTX_TRY_NUMBER='1' AIRFLOW_CTX_DAG_RUN_ID='manual__2023-10-23T12:31:01.467482+00:00'
[2023-10-23T12:45:17.049+0000] {local_task_job_runner.py:294} WARNING - State of this instance has been externally set to restarting. Terminating instance.
[2023-10-23T12:45:17.054+0000] {process_utils.py:131} INFO - Sending 15 to group 229. PIDs of all processes in the group: [229]
[2023-10-23T12:45:17.055+0000] {process_utils.py:86} INFO - Sending the signal 15 to group 229
[2023-10-23T12:45:17.055+0000] {taskinstance.py:1632} ERROR - Received SIGTERM. Terminating subprocesses.
[2023-10-23T12:45:17.068+0000] {taskinstance.py:1937} ERROR - Task failed with exception
Traceback (most recent call last):
  File "/home/airflow/.local/lib/python3.8/site-packages/airflow/operators/python.py", line 192, in execute
    return_value = self.execute_callable()
  File "/home/airflow/.local/lib/python3.8/site-packages/airflow/operators/python.py", line 209, in execute_callable
    return self.python_callable(*self.op_args, **self.op_kwargs)
  File "/opt/airflow/dags/fetch_and_save_data.py", line 55, in fetch_all_and_save
    sleep(4)
  File "/home/airflow/.local/lib/python3.8/site-packages/airflow/models/taskinstance.py", line 1634, in signal_handler
    raise AirflowException("Task received SIGTERM signal")
airflow.exceptions.AirflowException: Task received SIGTERM signal
[2023-10-23T12:45:17.074+0000] {taskinstance.py:1400} INFO - Marking task as UP_FOR_RETRY. dag_id=once_ingestion_gcs_dag, task_id=fetch_and_save_to_local_task, execution_date=20231023T123101, start_date=20231023T124149, end_date=20231023T124517
[2023-10-23T12:45:17.090+0000] {standard_task_runner.py:104} ERROR - Failed to execute job 6 for task fetch_and_save_to_local_task (Task received SIGTERM signal; 229)
[2023-10-23T12:45:17.148+0000] {process_utils.py:79} INFO - Process psutil.Process(pid=229, status='terminated', exitcode=1, started='12:41:49') (229) terminated with exit code 1
