[2023-10-23T13:40:15.016+0000] {taskinstance.py:1159} INFO - Dependencies all met for dep_context=non-requeueable deps ti=<TaskInstance: once_ingestion_gcs_dag.local_to_gcs_task manual__2023-10-23T13:34:37.389284+00:00 [queued]>
[2023-10-23T13:40:15.028+0000] {taskinstance.py:1159} INFO - Dependencies all met for dep_context=requeueable deps ti=<TaskInstance: once_ingestion_gcs_dag.local_to_gcs_task manual__2023-10-23T13:34:37.389284+00:00 [queued]>
[2023-10-23T13:40:15.029+0000] {taskinstance.py:1361} INFO - Starting attempt 1 of 2
[2023-10-23T13:40:15.049+0000] {taskinstance.py:1382} INFO - Executing <Task(PythonOperator): local_to_gcs_task> on 2023-10-23 13:34:37.389284+00:00
[2023-10-23T13:40:15.060+0000] {standard_task_runner.py:57} INFO - Started process 157 to run task
[2023-10-23T13:40:15.067+0000] {standard_task_runner.py:84} INFO - Running: ['***', 'tasks', 'run', 'once_ingestion_gcs_dag', 'local_to_gcs_task', 'manual__2023-10-23T13:34:37.389284+00:00', '--job-id', '15', '--raw', '--subdir', 'DAGS_FOLDER/once_ingest_data_to_gcs_dag.py', '--cfg-path', '/tmp/tmpmlqrwsxm']
[2023-10-23T13:40:15.073+0000] {standard_task_runner.py:85} INFO - Job 15: Subtask local_to_gcs_task
[2023-10-23T13:40:15.141+0000] {task_command.py:416} INFO - Running <TaskInstance: once_ingestion_gcs_dag.local_to_gcs_task manual__2023-10-23T13:34:37.389284+00:00 [running]> on host 01cb67bb8d92
[2023-10-23T13:40:15.255+0000] {taskinstance.py:1662} INFO - Exporting env vars: AIRFLOW_CTX_DAG_OWNER='***' AIRFLOW_CTX_DAG_ID='once_ingestion_gcs_dag' AIRFLOW_CTX_TASK_ID='local_to_gcs_task' AIRFLOW_CTX_EXECUTION_DATE='2023-10-23T13:34:37.389284+00:00' AIRFLOW_CTX_TRY_NUMBER='1' AIRFLOW_CTX_DAG_RUN_ID='manual__2023-10-23T13:34:37.389284+00:00'
[2023-10-23T13:40:15.267+0000] {taskinstance.py:1937} ERROR - Task failed with exception
Traceback (most recent call last):
  File "/home/airflow/.local/lib/python3.8/site-packages/airflow/operators/python.py", line 192, in execute
    return_value = self.execute_callable()
  File "/home/airflow/.local/lib/python3.8/site-packages/airflow/operators/python.py", line 209, in execute_callable
    return self.python_callable(*self.op_args, **self.op_kwargs)
  File "/opt/airflow/dags/upload_to_gcs.py", line 7, in upload_to_gcs
    client = storage.Client()
  File "/home/airflow/.local/lib/python3.8/site-packages/google/cloud/storage/client.py", line 166, in __init__
    super(Client, self).__init__(
  File "/home/airflow/.local/lib/python3.8/site-packages/google/cloud/client/__init__.py", line 320, in __init__
    _ClientProjectMixin.__init__(self, project=project, credentials=credentials)
  File "/home/airflow/.local/lib/python3.8/site-packages/google/cloud/client/__init__.py", line 268, in __init__
    project = self._determine_default(project)
  File "/home/airflow/.local/lib/python3.8/site-packages/google/cloud/client/__init__.py", line 287, in _determine_default
    return _determine_default_project(project)
  File "/home/airflow/.local/lib/python3.8/site-packages/google/cloud/_helpers/__init__.py", line 152, in _determine_default_project
    _, project = google.auth.default()
  File "/home/airflow/.local/lib/python3.8/site-packages/google/auth/_default.py", line 657, in default
    credentials, project_id = checker()
  File "/home/airflow/.local/lib/python3.8/site-packages/google/auth/_default.py", line 650, in <lambda>
    lambda: _get_explicit_environ_credentials(quota_project_id=quota_project_id),
  File "/home/airflow/.local/lib/python3.8/site-packages/google/auth/_default.py", line 270, in _get_explicit_environ_credentials
    credentials, project_id = load_credentials_from_file(
  File "/home/airflow/.local/lib/python3.8/site-packages/google/auth/_default.py", line 114, in load_credentials_from_file
    raise exceptions.DefaultCredentialsError(
google.auth.exceptions.DefaultCredentialsError: File /.google/credentials/de-zoomcamp-creds.json was not found.
[2023-10-23T13:40:15.290+0000] {taskinstance.py:1400} INFO - Marking task as UP_FOR_RETRY. dag_id=once_ingestion_gcs_dag, task_id=local_to_gcs_task, execution_date=20231023T133437, start_date=20231023T134015, end_date=20231023T134015
[2023-10-23T13:40:15.315+0000] {standard_task_runner.py:104} ERROR - Failed to execute job 15 for task local_to_gcs_task (File /.google/credentials/de-zoomcamp-creds.json was not found.; 157)
[2023-10-23T13:40:15.360+0000] {local_task_job_runner.py:228} INFO - Task exited with return code 1
[2023-10-23T13:40:15.473+0000] {taskinstance.py:2778} INFO - 0 downstream tasks scheduled from follow-on schedule check
