[2023-10-23T11:43:23.453+0000] {taskinstance.py:1159} INFO - Dependencies all met for dep_context=non-requeueable deps ti=<TaskInstance: once_ingestion_gcs_dag.local_to_gcs_task scheduled__2023-10-22T00:00:00+00:00 [queued]>
[2023-10-23T11:43:23.465+0000] {taskinstance.py:1159} INFO - Dependencies all met for dep_context=requeueable deps ti=<TaskInstance: once_ingestion_gcs_dag.local_to_gcs_task scheduled__2023-10-22T00:00:00+00:00 [queued]>
[2023-10-23T11:43:23.465+0000] {taskinstance.py:1361} INFO - Starting attempt 1 of 2
[2023-10-23T11:43:23.483+0000] {taskinstance.py:1382} INFO - Executing <Task(PythonOperator): local_to_gcs_task> on 2023-10-22 00:00:00+00:00
[2023-10-23T11:43:23.493+0000] {standard_task_runner.py:57} INFO - Started process 247 to run task
[2023-10-23T11:43:23.501+0000] {standard_task_runner.py:84} INFO - Running: ['***', 'tasks', 'run', 'once_ingestion_gcs_dag', 'local_to_gcs_task', 'scheduled__2023-10-22T00:00:00+00:00', '--job-id', '10', '--raw', '--subdir', 'DAGS_FOLDER/once_ingest_data_to_gcs_dag.py', '--cfg-path', '/tmp/tmpzzlno73d']
[2023-10-23T11:43:23.506+0000] {standard_task_runner.py:85} INFO - Job 10: Subtask local_to_gcs_task
[2023-10-23T11:43:23.591+0000] {task_command.py:416} INFO - Running <TaskInstance: once_ingestion_gcs_dag.local_to_gcs_task scheduled__2023-10-22T00:00:00+00:00 [running]> on host f3bb9335c956
[2023-10-23T11:43:23.703+0000] {taskinstance.py:1662} INFO - Exporting env vars: AIRFLOW_CTX_DAG_OWNER='***' AIRFLOW_CTX_DAG_ID='once_ingestion_gcs_dag' AIRFLOW_CTX_TASK_ID='local_to_gcs_task' AIRFLOW_CTX_EXECUTION_DATE='2023-10-22T00:00:00+00:00' AIRFLOW_CTX_TRY_NUMBER='1' AIRFLOW_CTX_DAG_RUN_ID='scheduled__2023-10-22T00:00:00+00:00'
[2023-10-23T11:43:23.709+0000] {taskinstance.py:1937} ERROR - Task failed with exception
Traceback (most recent call last):
  File "/home/airflow/.local/lib/python3.8/site-packages/airflow/operators/python.py", line 192, in execute
    return_value = self.execute_callable()
  File "/home/airflow/.local/lib/python3.8/site-packages/airflow/operators/python.py", line 209, in execute_callable
    return self.python_callable(*self.op_args, **self.op_kwargs)
  File "/opt/airflow/dags/upload_to_gcs.py", line 7, in upload_to_gcs
    client = storage.Client()
  File "/home/airflow/.local/lib/python3.8/site-packages/google/cloud/storage/client.py", line 166, in __init__
    super(Client, self).__init__(
  File "/home/airflow/.local/lib/python3.8/site-packages/google/cloud/client/__init__.py", line 320, in __init__
    _ClientProjectMixin.__init__(self, project=project, credentials=credentials)
  File "/home/airflow/.local/lib/python3.8/site-packages/google/cloud/client/__init__.py", line 268, in __init__
    project = self._determine_default(project)
  File "/home/airflow/.local/lib/python3.8/site-packages/google/cloud/client/__init__.py", line 287, in _determine_default
    return _determine_default_project(project)
  File "/home/airflow/.local/lib/python3.8/site-packages/google/cloud/_helpers/__init__.py", line 152, in _determine_default_project
    _, project = google.auth.default()
  File "/home/airflow/.local/lib/python3.8/site-packages/google/auth/_default.py", line 657, in default
    credentials, project_id = checker()
  File "/home/airflow/.local/lib/python3.8/site-packages/google/auth/_default.py", line 650, in <lambda>
    lambda: _get_explicit_environ_credentials(quota_project_id=quota_project_id),
  File "/home/airflow/.local/lib/python3.8/site-packages/google/auth/_default.py", line 270, in _get_explicit_environ_credentials
    credentials, project_id = load_credentials_from_file(
  File "/home/airflow/.local/lib/python3.8/site-packages/google/auth/_default.py", line 114, in load_credentials_from_file
    raise exceptions.DefaultCredentialsError(
google.auth.exceptions.DefaultCredentialsError: File /.google/credentials/de-zoomcamp-creds.json was not found.
[2023-10-23T11:43:23.726+0000] {taskinstance.py:1400} INFO - Marking task as UP_FOR_RETRY. dag_id=once_ingestion_gcs_dag, task_id=local_to_gcs_task, execution_date=20231022T000000, start_date=20231023T114323, end_date=20231023T114323
[2023-10-23T11:43:23.743+0000] {standard_task_runner.py:104} ERROR - Failed to execute job 10 for task local_to_gcs_task (File /.google/credentials/de-zoomcamp-creds.json was not found.; 247)
[2023-10-23T11:43:23.793+0000] {local_task_job_runner.py:228} INFO - Task exited with return code 1
[2023-10-23T11:43:23.831+0000] {taskinstance.py:2778} INFO - 0 downstream tasks scheduled from follow-on schedule check
[2023-10-23T12:36:44.341+0000] {taskinstance.py:1159} INFO - Dependencies all met for dep_context=non-requeueable deps ti=<TaskInstance: once_ingestion_gcs_dag.local_to_gcs_task scheduled__2023-10-22T00:00:00+00:00 [queued]>
[2023-10-23T12:36:44.354+0000] {taskinstance.py:1159} INFO - Dependencies all met for dep_context=requeueable deps ti=<TaskInstance: once_ingestion_gcs_dag.local_to_gcs_task scheduled__2023-10-22T00:00:00+00:00 [queued]>
[2023-10-23T12:36:44.355+0000] {taskinstance.py:1361} INFO - Starting attempt 1 of 2
[2023-10-23T12:36:44.373+0000] {taskinstance.py:1382} INFO - Executing <Task(PythonOperator): local_to_gcs_task> on 2023-10-22 00:00:00+00:00
[2023-10-23T12:36:44.383+0000] {standard_task_runner.py:57} INFO - Started process 150 to run task
[2023-10-23T12:36:44.390+0000] {standard_task_runner.py:84} INFO - Running: ['***', 'tasks', 'run', 'once_ingestion_gcs_dag', 'local_to_gcs_task', 'scheduled__2023-10-22T00:00:00+00:00', '--job-id', '4', '--raw', '--subdir', 'DAGS_FOLDER/once_ingest_data_to_gcs_dag.py', '--cfg-path', '/tmp/tmphwpg9yny']
[2023-10-23T12:36:44.395+0000] {standard_task_runner.py:85} INFO - Job 4: Subtask local_to_gcs_task
[2023-10-23T12:36:44.467+0000] {task_command.py:416} INFO - Running <TaskInstance: once_ingestion_gcs_dag.local_to_gcs_task scheduled__2023-10-22T00:00:00+00:00 [running]> on host c698a5494e22
[2023-10-23T12:36:44.570+0000] {taskinstance.py:1662} INFO - Exporting env vars: AIRFLOW_CTX_DAG_OWNER='***' AIRFLOW_CTX_DAG_ID='once_ingestion_gcs_dag' AIRFLOW_CTX_TASK_ID='local_to_gcs_task' AIRFLOW_CTX_EXECUTION_DATE='2023-10-22T00:00:00+00:00' AIRFLOW_CTX_TRY_NUMBER='1' AIRFLOW_CTX_DAG_RUN_ID='scheduled__2023-10-22T00:00:00+00:00'
[2023-10-23T12:36:44.574+0000] {taskinstance.py:1937} ERROR - Task failed with exception
Traceback (most recent call last):
  File "/home/airflow/.local/lib/python3.8/site-packages/airflow/operators/python.py", line 192, in execute
    return_value = self.execute_callable()
  File "/home/airflow/.local/lib/python3.8/site-packages/airflow/operators/python.py", line 209, in execute_callable
    return self.python_callable(*self.op_args, **self.op_kwargs)
  File "/opt/airflow/dags/upload_to_gcs.py", line 7, in upload_to_gcs
    client = storage.Client()
  File "/home/airflow/.local/lib/python3.8/site-packages/google/cloud/storage/client.py", line 166, in __init__
    super(Client, self).__init__(
  File "/home/airflow/.local/lib/python3.8/site-packages/google/cloud/client/__init__.py", line 320, in __init__
    _ClientProjectMixin.__init__(self, project=project, credentials=credentials)
  File "/home/airflow/.local/lib/python3.8/site-packages/google/cloud/client/__init__.py", line 268, in __init__
    project = self._determine_default(project)
  File "/home/airflow/.local/lib/python3.8/site-packages/google/cloud/client/__init__.py", line 287, in _determine_default
    return _determine_default_project(project)
  File "/home/airflow/.local/lib/python3.8/site-packages/google/cloud/_helpers/__init__.py", line 152, in _determine_default_project
    _, project = google.auth.default()
  File "/home/airflow/.local/lib/python3.8/site-packages/google/auth/_default.py", line 657, in default
    credentials, project_id = checker()
  File "/home/airflow/.local/lib/python3.8/site-packages/google/auth/_default.py", line 650, in <lambda>
    lambda: _get_explicit_environ_credentials(quota_project_id=quota_project_id),
  File "/home/airflow/.local/lib/python3.8/site-packages/google/auth/_default.py", line 270, in _get_explicit_environ_credentials
    credentials, project_id = load_credentials_from_file(
  File "/home/airflow/.local/lib/python3.8/site-packages/google/auth/_default.py", line 114, in load_credentials_from_file
    raise exceptions.DefaultCredentialsError(
google.auth.exceptions.DefaultCredentialsError: File /.google/de-zoomcamp-creds.json was not found.
[2023-10-23T12:36:44.588+0000] {taskinstance.py:1400} INFO - Marking task as UP_FOR_RETRY. dag_id=once_ingestion_gcs_dag, task_id=local_to_gcs_task, execution_date=20231022T000000, start_date=20231023T123644, end_date=20231023T123644
[2023-10-23T12:36:44.604+0000] {standard_task_runner.py:104} ERROR - Failed to execute job 4 for task local_to_gcs_task (File /.google/de-zoomcamp-creds.json was not found.; 150)
[2023-10-23T12:36:44.643+0000] {local_task_job_runner.py:228} INFO - Task exited with return code 1
[2023-10-23T12:36:44.675+0000] {taskinstance.py:2778} INFO - 0 downstream tasks scheduled from follow-on schedule check
[2023-10-23T13:17:19.190+0000] {taskinstance.py:1159} INFO - Dependencies all met for dep_context=non-requeueable deps ti=<TaskInstance: once_ingestion_gcs_dag.local_to_gcs_task scheduled__2023-10-22T00:00:00+00:00 [queued]>
[2023-10-23T13:17:19.203+0000] {taskinstance.py:1159} INFO - Dependencies all met for dep_context=requeueable deps ti=<TaskInstance: once_ingestion_gcs_dag.local_to_gcs_task scheduled__2023-10-22T00:00:00+00:00 [queued]>
[2023-10-23T13:17:19.204+0000] {taskinstance.py:1361} INFO - Starting attempt 1 of 2
[2023-10-23T13:17:19.223+0000] {taskinstance.py:1382} INFO - Executing <Task(PythonOperator): local_to_gcs_task> on 2023-10-22 00:00:00+00:00
[2023-10-23T13:17:19.234+0000] {standard_task_runner.py:57} INFO - Started process 178 to run task
[2023-10-23T13:17:19.241+0000] {standard_task_runner.py:84} INFO - Running: ['***', 'tasks', 'run', 'once_ingestion_gcs_dag', 'local_to_gcs_task', 'scheduled__2023-10-22T00:00:00+00:00', '--job-id', '10', '--raw', '--subdir', 'DAGS_FOLDER/once_ingest_data_to_gcs_dag.py', '--cfg-path', '/tmp/tmpctxqypqu']
[2023-10-23T13:17:19.247+0000] {standard_task_runner.py:85} INFO - Job 10: Subtask local_to_gcs_task
[2023-10-23T13:17:19.319+0000] {task_command.py:416} INFO - Running <TaskInstance: once_ingestion_gcs_dag.local_to_gcs_task scheduled__2023-10-22T00:00:00+00:00 [running]> on host 913d4cde6d10
[2023-10-23T13:17:19.424+0000] {taskinstance.py:1662} INFO - Exporting env vars: AIRFLOW_CTX_DAG_OWNER='***' AIRFLOW_CTX_DAG_ID='once_ingestion_gcs_dag' AIRFLOW_CTX_TASK_ID='local_to_gcs_task' AIRFLOW_CTX_EXECUTION_DATE='2023-10-22T00:00:00+00:00' AIRFLOW_CTX_TRY_NUMBER='1' AIRFLOW_CTX_DAG_RUN_ID='scheduled__2023-10-22T00:00:00+00:00'
[2023-10-23T13:17:19.431+0000] {taskinstance.py:1937} ERROR - Task failed with exception
Traceback (most recent call last):
  File "/home/airflow/.local/lib/python3.8/site-packages/airflow/operators/python.py", line 192, in execute
    return_value = self.execute_callable()
  File "/home/airflow/.local/lib/python3.8/site-packages/airflow/operators/python.py", line 209, in execute_callable
    return self.python_callable(*self.op_args, **self.op_kwargs)
  File "/opt/airflow/dags/upload_to_gcs.py", line 7, in upload_to_gcs
    client = storage.Client()
  File "/home/airflow/.local/lib/python3.8/site-packages/google/cloud/storage/client.py", line 166, in __init__
    super(Client, self).__init__(
  File "/home/airflow/.local/lib/python3.8/site-packages/google/cloud/client/__init__.py", line 320, in __init__
    _ClientProjectMixin.__init__(self, project=project, credentials=credentials)
  File "/home/airflow/.local/lib/python3.8/site-packages/google/cloud/client/__init__.py", line 268, in __init__
    project = self._determine_default(project)
  File "/home/airflow/.local/lib/python3.8/site-packages/google/cloud/client/__init__.py", line 287, in _determine_default
    return _determine_default_project(project)
  File "/home/airflow/.local/lib/python3.8/site-packages/google/cloud/_helpers/__init__.py", line 152, in _determine_default_project
    _, project = google.auth.default()
  File "/home/airflow/.local/lib/python3.8/site-packages/google/auth/_default.py", line 657, in default
    credentials, project_id = checker()
  File "/home/airflow/.local/lib/python3.8/site-packages/google/auth/_default.py", line 650, in <lambda>
    lambda: _get_explicit_environ_credentials(quota_project_id=quota_project_id),
  File "/home/airflow/.local/lib/python3.8/site-packages/google/auth/_default.py", line 270, in _get_explicit_environ_credentials
    credentials, project_id = load_credentials_from_file(
  File "/home/airflow/.local/lib/python3.8/site-packages/google/auth/_default.py", line 114, in load_credentials_from_file
    raise exceptions.DefaultCredentialsError(
google.auth.exceptions.DefaultCredentialsError: File /.google/credentials/de-zoomcamp-creds.json was not found.
[2023-10-23T13:17:19.446+0000] {taskinstance.py:1400} INFO - Marking task as UP_FOR_RETRY. dag_id=once_ingestion_gcs_dag, task_id=local_to_gcs_task, execution_date=20231022T000000, start_date=20231023T131719, end_date=20231023T131719
[2023-10-23T13:17:19.465+0000] {standard_task_runner.py:104} ERROR - Failed to execute job 10 for task local_to_gcs_task (File /.google/credentials/de-zoomcamp-creds.json was not found.; 178)
[2023-10-23T13:17:19.494+0000] {local_task_job_runner.py:228} INFO - Task exited with return code 1
[2023-10-23T13:17:19.533+0000] {taskinstance.py:2778} INFO - 0 downstream tasks scheduled from follow-on schedule check
[2023-10-23T16:55:31.454+0000] {taskinstance.py:1159} INFO - Dependencies all met for dep_context=non-requeueable deps ti=<TaskInstance: once_ingestion_gcs_dag.local_to_gcs_task scheduled__2023-10-22T00:00:00+00:00 [queued]>
[2023-10-23T16:55:31.473+0000] {taskinstance.py:1159} INFO - Dependencies all met for dep_context=requeueable deps ti=<TaskInstance: once_ingestion_gcs_dag.local_to_gcs_task scheduled__2023-10-22T00:00:00+00:00 [queued]>
[2023-10-23T16:55:31.473+0000] {taskinstance.py:1361} INFO - Starting attempt 1 of 2
[2023-10-23T16:55:31.492+0000] {taskinstance.py:1382} INFO - Executing <Task(PythonOperator): local_to_gcs_task> on 2023-10-22 00:00:00+00:00
[2023-10-23T16:55:31.501+0000] {standard_task_runner.py:57} INFO - Started process 277 to run task
[2023-10-23T16:55:31.505+0000] {standard_task_runner.py:84} INFO - Running: ['***', 'tasks', 'run', 'once_ingestion_gcs_dag', 'local_to_gcs_task', 'scheduled__2023-10-22T00:00:00+00:00', '--job-id', '10', '--raw', '--subdir', 'DAGS_FOLDER/once_ingest_data_to_gcs_dag.py', '--cfg-path', '/tmp/tmpl7gs5zwl']
[2023-10-23T16:55:31.508+0000] {standard_task_runner.py:85} INFO - Job 10: Subtask local_to_gcs_task
[2023-10-23T16:55:31.554+0000] {task_command.py:416} INFO - Running <TaskInstance: once_ingestion_gcs_dag.local_to_gcs_task scheduled__2023-10-22T00:00:00+00:00 [running]> on host 18162411be33
[2023-10-23T16:55:31.631+0000] {taskinstance.py:1662} INFO - Exporting env vars: AIRFLOW_CTX_DAG_OWNER='***' AIRFLOW_CTX_DAG_ID='once_ingestion_gcs_dag' AIRFLOW_CTX_TASK_ID='local_to_gcs_task' AIRFLOW_CTX_EXECUTION_DATE='2023-10-22T00:00:00+00:00' AIRFLOW_CTX_TRY_NUMBER='1' AIRFLOW_CTX_DAG_RUN_ID='scheduled__2023-10-22T00:00:00+00:00'
[2023-10-23T16:55:32.474+0000] {python.py:194} INFO - Done. Returned value was: None
[2023-10-23T16:55:32.490+0000] {taskinstance.py:1400} INFO - Marking task as SUCCESS. dag_id=once_ingestion_gcs_dag, task_id=local_to_gcs_task, execution_date=20231022T000000, start_date=20231023T165531, end_date=20231023T165532
[2023-10-23T16:55:32.520+0000] {local_task_job_runner.py:228} INFO - Task exited with return code 0
[2023-10-23T16:55:32.559+0000] {taskinstance.py:2778} INFO - 0 downstream tasks scheduled from follow-on schedule check
