[2023-10-23T12:41:46.450+0000] {taskinstance.py:1159} INFO - Dependencies all met for dep_context=non-requeueable deps ti=<TaskInstance: once_ingestion_gcs_dag.local_to_gcs_task scheduled__2023-10-22T00:00:00+00:00 [queued]>
[2023-10-23T12:41:46.462+0000] {taskinstance.py:1159} INFO - Dependencies all met for dep_context=requeueable deps ti=<TaskInstance: once_ingestion_gcs_dag.local_to_gcs_task scheduled__2023-10-22T00:00:00+00:00 [queued]>
[2023-10-23T12:41:46.463+0000] {taskinstance.py:1361} INFO - Starting attempt 2 of 2
[2023-10-23T12:41:46.481+0000] {taskinstance.py:1382} INFO - Executing <Task(PythonOperator): local_to_gcs_task> on 2023-10-22 00:00:00+00:00
[2023-10-23T12:41:46.493+0000] {standard_task_runner.py:57} INFO - Started process 226 to run task
[2023-10-23T12:41:46.501+0000] {standard_task_runner.py:84} INFO - Running: ['***', 'tasks', 'run', 'once_ingestion_gcs_dag', 'local_to_gcs_task', 'scheduled__2023-10-22T00:00:00+00:00', '--job-id', '5', '--raw', '--subdir', 'DAGS_FOLDER/once_ingest_data_to_gcs_dag.py', '--cfg-path', '/tmp/tmp4eol_g_6']
[2023-10-23T12:41:46.506+0000] {standard_task_runner.py:85} INFO - Job 5: Subtask local_to_gcs_task
[2023-10-23T12:41:46.578+0000] {task_command.py:416} INFO - Running <TaskInstance: once_ingestion_gcs_dag.local_to_gcs_task scheduled__2023-10-22T00:00:00+00:00 [running]> on host c698a5494e22
[2023-10-23T12:41:46.683+0000] {taskinstance.py:1662} INFO - Exporting env vars: AIRFLOW_CTX_DAG_OWNER='***' AIRFLOW_CTX_DAG_ID='once_ingestion_gcs_dag' AIRFLOW_CTX_TASK_ID='local_to_gcs_task' AIRFLOW_CTX_EXECUTION_DATE='2023-10-22T00:00:00+00:00' AIRFLOW_CTX_TRY_NUMBER='2' AIRFLOW_CTX_DAG_RUN_ID='scheduled__2023-10-22T00:00:00+00:00'
[2023-10-23T12:41:46.688+0000] {taskinstance.py:1937} ERROR - Task failed with exception
Traceback (most recent call last):
  File "/home/airflow/.local/lib/python3.8/site-packages/airflow/operators/python.py", line 192, in execute
    return_value = self.execute_callable()
  File "/home/airflow/.local/lib/python3.8/site-packages/airflow/operators/python.py", line 209, in execute_callable
    return self.python_callable(*self.op_args, **self.op_kwargs)
  File "/opt/airflow/dags/upload_to_gcs.py", line 7, in upload_to_gcs
    client = storage.Client()
  File "/home/airflow/.local/lib/python3.8/site-packages/google/cloud/storage/client.py", line 166, in __init__
    super(Client, self).__init__(
  File "/home/airflow/.local/lib/python3.8/site-packages/google/cloud/client/__init__.py", line 320, in __init__
    _ClientProjectMixin.__init__(self, project=project, credentials=credentials)
  File "/home/airflow/.local/lib/python3.8/site-packages/google/cloud/client/__init__.py", line 268, in __init__
    project = self._determine_default(project)
  File "/home/airflow/.local/lib/python3.8/site-packages/google/cloud/client/__init__.py", line 287, in _determine_default
    return _determine_default_project(project)
  File "/home/airflow/.local/lib/python3.8/site-packages/google/cloud/_helpers/__init__.py", line 152, in _determine_default_project
    _, project = google.auth.default()
  File "/home/airflow/.local/lib/python3.8/site-packages/google/auth/_default.py", line 657, in default
    credentials, project_id = checker()
  File "/home/airflow/.local/lib/python3.8/site-packages/google/auth/_default.py", line 650, in <lambda>
    lambda: _get_explicit_environ_credentials(quota_project_id=quota_project_id),
  File "/home/airflow/.local/lib/python3.8/site-packages/google/auth/_default.py", line 270, in _get_explicit_environ_credentials
    credentials, project_id = load_credentials_from_file(
  File "/home/airflow/.local/lib/python3.8/site-packages/google/auth/_default.py", line 114, in load_credentials_from_file
    raise exceptions.DefaultCredentialsError(
google.auth.exceptions.DefaultCredentialsError: File /.google/de-zoomcamp-creds.json was not found.
[2023-10-23T12:41:46.705+0000] {taskinstance.py:1400} INFO - Marking task as FAILED. dag_id=once_ingestion_gcs_dag, task_id=local_to_gcs_task, execution_date=20231022T000000, start_date=20231023T124146, end_date=20231023T124146
[2023-10-23T12:41:46.723+0000] {standard_task_runner.py:104} ERROR - Failed to execute job 5 for task local_to_gcs_task (File /.google/de-zoomcamp-creds.json was not found.; 226)
[2023-10-23T12:41:46.754+0000] {local_task_job_runner.py:228} INFO - Task exited with return code 1
[2023-10-23T12:41:46.787+0000] {taskinstance.py:2778} INFO - 0 downstream tasks scheduled from follow-on schedule check
[2023-10-23T13:22:21.181+0000] {taskinstance.py:1159} INFO - Dependencies all met for dep_context=non-requeueable deps ti=<TaskInstance: once_ingestion_gcs_dag.local_to_gcs_task scheduled__2023-10-22T00:00:00+00:00 [queued]>
[2023-10-23T13:22:21.196+0000] {taskinstance.py:1159} INFO - Dependencies all met for dep_context=requeueable deps ti=<TaskInstance: once_ingestion_gcs_dag.local_to_gcs_task scheduled__2023-10-22T00:00:00+00:00 [queued]>
[2023-10-23T13:22:21.196+0000] {taskinstance.py:1361} INFO - Starting attempt 2 of 2
[2023-10-23T13:22:21.215+0000] {taskinstance.py:1382} INFO - Executing <Task(PythonOperator): local_to_gcs_task> on 2023-10-22 00:00:00+00:00
[2023-10-23T13:22:21.226+0000] {standard_task_runner.py:57} INFO - Started process 255 to run task
[2023-10-23T13:22:21.233+0000] {standard_task_runner.py:84} INFO - Running: ['***', 'tasks', 'run', 'once_ingestion_gcs_dag', 'local_to_gcs_task', 'scheduled__2023-10-22T00:00:00+00:00', '--job-id', '11', '--raw', '--subdir', 'DAGS_FOLDER/once_ingest_data_to_gcs_dag.py', '--cfg-path', '/tmp/tmpnazqd7xp']
[2023-10-23T13:22:21.242+0000] {standard_task_runner.py:85} INFO - Job 11: Subtask local_to_gcs_task
[2023-10-23T13:22:21.390+0000] {task_command.py:416} INFO - Running <TaskInstance: once_ingestion_gcs_dag.local_to_gcs_task scheduled__2023-10-22T00:00:00+00:00 [running]> on host 913d4cde6d10
[2023-10-23T13:22:21.542+0000] {taskinstance.py:1662} INFO - Exporting env vars: AIRFLOW_CTX_DAG_OWNER='***' AIRFLOW_CTX_DAG_ID='once_ingestion_gcs_dag' AIRFLOW_CTX_TASK_ID='local_to_gcs_task' AIRFLOW_CTX_EXECUTION_DATE='2023-10-22T00:00:00+00:00' AIRFLOW_CTX_TRY_NUMBER='2' AIRFLOW_CTX_DAG_RUN_ID='scheduled__2023-10-22T00:00:00+00:00'
[2023-10-23T13:22:21.553+0000] {taskinstance.py:1937} ERROR - Task failed with exception
Traceback (most recent call last):
  File "/home/airflow/.local/lib/python3.8/site-packages/airflow/operators/python.py", line 192, in execute
    return_value = self.execute_callable()
  File "/home/airflow/.local/lib/python3.8/site-packages/airflow/operators/python.py", line 209, in execute_callable
    return self.python_callable(*self.op_args, **self.op_kwargs)
  File "/opt/airflow/dags/upload_to_gcs.py", line 7, in upload_to_gcs
    client = storage.Client()
  File "/home/airflow/.local/lib/python3.8/site-packages/google/cloud/storage/client.py", line 166, in __init__
    super(Client, self).__init__(
  File "/home/airflow/.local/lib/python3.8/site-packages/google/cloud/client/__init__.py", line 320, in __init__
    _ClientProjectMixin.__init__(self, project=project, credentials=credentials)
  File "/home/airflow/.local/lib/python3.8/site-packages/google/cloud/client/__init__.py", line 268, in __init__
    project = self._determine_default(project)
  File "/home/airflow/.local/lib/python3.8/site-packages/google/cloud/client/__init__.py", line 287, in _determine_default
    return _determine_default_project(project)
  File "/home/airflow/.local/lib/python3.8/site-packages/google/cloud/_helpers/__init__.py", line 152, in _determine_default_project
    _, project = google.auth.default()
  File "/home/airflow/.local/lib/python3.8/site-packages/google/auth/_default.py", line 657, in default
    credentials, project_id = checker()
  File "/home/airflow/.local/lib/python3.8/site-packages/google/auth/_default.py", line 650, in <lambda>
    lambda: _get_explicit_environ_credentials(quota_project_id=quota_project_id),
  File "/home/airflow/.local/lib/python3.8/site-packages/google/auth/_default.py", line 270, in _get_explicit_environ_credentials
    credentials, project_id = load_credentials_from_file(
  File "/home/airflow/.local/lib/python3.8/site-packages/google/auth/_default.py", line 114, in load_credentials_from_file
    raise exceptions.DefaultCredentialsError(
google.auth.exceptions.DefaultCredentialsError: File /.google/credentials/de-zoomcamp-creds.json was not found.
[2023-10-23T13:22:21.572+0000] {taskinstance.py:1400} INFO - Marking task as FAILED. dag_id=once_ingestion_gcs_dag, task_id=local_to_gcs_task, execution_date=20231022T000000, start_date=20231023T132221, end_date=20231023T132221
[2023-10-23T13:22:21.596+0000] {standard_task_runner.py:104} ERROR - Failed to execute job 11 for task local_to_gcs_task (File /.google/credentials/de-zoomcamp-creds.json was not found.; 255)
[2023-10-23T13:22:21.654+0000] {local_task_job_runner.py:228} INFO - Task exited with return code 1
[2023-10-23T13:22:21.688+0000] {taskinstance.py:2778} INFO - 0 downstream tasks scheduled from follow-on schedule check
