[2023-10-23T13:53:53.845+0000] {taskinstance.py:1159} INFO - Dependencies all met for dep_context=non-requeueable deps ti=<TaskInstance: daily_ingestion_gcs_dag.fetch_and_save_to_local_task scheduled__2023-10-22T00:00:00+00:00 [queued]>
[2023-10-23T13:53:53.860+0000] {taskinstance.py:1159} INFO - Dependencies all met for dep_context=requeueable deps ti=<TaskInstance: daily_ingestion_gcs_dag.fetch_and_save_to_local_task scheduled__2023-10-22T00:00:00+00:00 [queued]>
[2023-10-23T13:53:53.861+0000] {taskinstance.py:1361} INFO - Starting attempt 1 of 2
[2023-10-23T13:53:53.889+0000] {taskinstance.py:1382} INFO - Executing <Task(PythonOperator): fetch_and_save_to_local_task> on 2023-10-22 00:00:00+00:00
[2023-10-23T13:53:53.897+0000] {standard_task_runner.py:57} INFO - Started process 71 to run task
[2023-10-23T13:53:53.905+0000] {standard_task_runner.py:84} INFO - Running: ['***', 'tasks', 'run', 'daily_ingestion_gcs_dag', 'fetch_and_save_to_local_task', 'scheduled__2023-10-22T00:00:00+00:00', '--job-id', '19', '--raw', '--subdir', 'DAGS_FOLDER/daily_ingest_data_to_gcs_dag.py', '--cfg-path', '/tmp/tmpi1qfi5j1']
[2023-10-23T13:53:53.912+0000] {standard_task_runner.py:85} INFO - Job 19: Subtask fetch_and_save_to_local_task
[2023-10-23T13:53:53.993+0000] {task_command.py:416} INFO - Running <TaskInstance: daily_ingestion_gcs_dag.fetch_and_save_to_local_task scheduled__2023-10-22T00:00:00+00:00 [running]> on host 32c3aa7698af
[2023-10-23T13:53:54.110+0000] {taskinstance.py:1662} INFO - Exporting env vars: AIRFLOW_CTX_DAG_OWNER='***' AIRFLOW_CTX_DAG_ID='daily_ingestion_gcs_dag' AIRFLOW_CTX_TASK_ID='fetch_and_save_to_local_task' AIRFLOW_CTX_EXECUTION_DATE='2023-10-22T00:00:00+00:00' AIRFLOW_CTX_TRY_NUMBER='1' AIRFLOW_CTX_DAG_RUN_ID='scheduled__2023-10-22T00:00:00+00:00'
[2023-10-23T13:53:54.113+0000] {taskinstance.py:1937} ERROR - Task failed with exception
Traceback (most recent call last):
  File "/home/airflow/.local/lib/python3.8/site-packages/airflow/operators/python.py", line 192, in execute
    return_value = self.execute_callable()
  File "/home/airflow/.local/lib/python3.8/site-packages/airflow/operators/python.py", line 209, in execute_callable
    return self.python_callable(*self.op_args, **self.op_kwargs)
TypeError: fetch_all_and_save() missing 1 required positional argument: 'path'
[2023-10-23T13:53:54.127+0000] {taskinstance.py:1400} INFO - Marking task as UP_FOR_RETRY. dag_id=daily_ingestion_gcs_dag, task_id=fetch_and_save_to_local_task, execution_date=20231022T000000, start_date=20231023T135353, end_date=20231023T135354
[2023-10-23T13:53:54.146+0000] {standard_task_runner.py:104} ERROR - Failed to execute job 19 for task fetch_and_save_to_local_task (fetch_all_and_save() missing 1 required positional argument: 'path'; 71)
[2023-10-23T13:53:54.159+0000] {local_task_job_runner.py:228} INFO - Task exited with return code 1
[2023-10-23T13:53:54.195+0000] {taskinstance.py:2778} INFO - 0 downstream tasks scheduled from follow-on schedule check
